<mujoco model="husky_robot">
  <compiler angle="radian" meshdir="./mesh/" autolimits="true"/>
  <!-- Default -->
  <default>
    <joint limited="false" armature="0.01" /> <!-- rolling joint -->
    <equality solref="0.0002 1" solimp="0.99 0.99 0.0001" />
  </default>
  <asset>
    <mesh name="base_link" file="base_link.stl"/>
    <mesh name="wheel" file="wheel.stl"/>
    <mesh name="top_plate" file="top_plate.stl"/>
    <mesh name="user_rail" file="user_rail.stl"/>
    <mesh name="bumper" file="bumper.stl"/>
  </asset>
  <worldbody>
    <body name="base_husky" pos="0 0 0.5" euler="0 0 0" >
      <inertial pos="0 0 0" quat="0.5 0.5 -0.5 0.5" mass="2.637" diaginertia="0.04411 0.02467 0.02467"/>
      <joint type="free" name="base_husky_joint" />
      <geom pos="0 0 0.14493" type="mesh" contype="0" conaffinity="0" group="1" density="0" rgba="0.1 0.1 0.1 1" mesh="base_link"/>
      <geom pos="0 0 0.14493" type="mesh" contype="0" conaffinity="0" group="1" density="0" rgba="0.8 0.8 0 1" mesh="top_plate"/>
      <geom pos="0.272 0 0.38993" type="mesh" contype="0" conaffinity="0" group="1" density="0" rgba="0.3 0.3 0.3 1" mesh="user_rail"/>
      <geom pos="0.48 0 0.23593" type="mesh" contype="0" conaffinity="0" group="1" density="0" rgba="0.3 0.3 0.3 1" mesh="bumper"/>
      <geom pos="-0.48 0 0.23593" quat="1.32679e-06 0 0 1" type="mesh" contype="0" conaffinity="0" group="1" density="0" rgba="0.3 0.3 0.3 1" mesh="bumper"/>
      <body name="front_left_wheel_link" pos="0.256 0.2854 0.17775" gravcomp="0">
        <inertial pos="0 0 0" quat="0.5 0.5 -0.5 0.5" mass="2.637" diaginertia="0.04411 0.02467 0.02467"/>
        <joint name="front_left_wheel" pos="0 0 0" axis="0 1 0"/>
        <geom type="mesh" contype="0" conaffinity="1" group="1" density="0" rgba="0.3 0.3 0.3 1" mesh="wheel"/>
        <!-- <geom size="0.17775 0.05715" quat="0.707107 0.707106 0 0" type="cylinder" rgba="0.3 0.3 0.3 1"/> -->
      </body>
      <body name="front_right_wheel_link" pos="0.256 -0.2854 0.17775" gravcomp="0">
        <inertial pos="0 0 0" quat="0.5 0.5 -0.5 0.5" mass="2.637" diaginertia="0.04411 0.02467 0.02467"/>
        <joint name="front_right_wheel" pos="0 0 0" axis="0 1 0"/>
        <geom type="mesh" contype="0" conaffinity="1" group="1" density="0" rgba="0.3 0.3 0.3 1" mesh="wheel"/>
        <!-- <geom size="0.17775 0.05715" quat="0.707107 0.707106 0 0" type="cylinder" rgba="0.3 0.3 0.3 1"/> -->
      </body>
      <body name="rear_left_wheel_link" pos="-0.256 0.2854 0.17775" gravcomp="0">
        <inertial pos="0 0 0" quat="0.5 0.5 -0.5 0.5" mass="2.637" diaginertia="0.04411 0.02467 0.02467"/>
        <joint name="rear_left_wheel" pos="0 0 0" axis="0 1 0"/>
        <geom type="mesh" contype="0" conaffinity="1" group="1" density="0" rgba="0.3 0.3 0.3 1" mesh="wheel"/>
        <!-- <geom size="0.17775 0.05715" quat="0.707107 0.707106 0 0" type="cylinder" rgba="0.3 0.3 0.3 1"/> -->
      </body>
      <body name="rear_right_wheel_link" pos="-0.256 -0.2854 0.17775" gravcomp="0">
        <inertial pos="0 0 0" quat="0.5 0.5 -0.5 0.5" mass="2.637" diaginertia="0.04411 0.02467 0.02467"/>
        <joint name="rear_right_wheel" pos="0 0 0" axis="0 1 0"/>
        <geom type="mesh" contype="0" conaffinity="1" group="1" density="0" rgba="0.3 0.3 0.3 1" mesh="wheel"/>
        <!-- <geom size="0.17775 0.05715" quat="0.707107 0.707106 0 0" type="cylinder" rgba="0.3 0.3 0.3 1"/> -->
      </body>  
    </body>
  </worldbody>
</mujoco>
