<mujocoinclude>
    <body name="panda_right_gripper" pos="0 0 0" quat="0.707107 0 0 -0.707107">
        <site name="panda_ft_frame" pos="0 0 0" size="0.01 0.01 0.01" rgba="1 0 0 1" type="sphere" group="1"/>
        <inertial pos="0 0 0.17" quat="0.707107 0.707107 0 0" mass="0.3" diaginertia="0.09 0.07 0.05" />
        <geom pos="0 0 0." quat="0.707107 0 0 0.707107" type="mesh" contype="0" conaffinity="0" group="1" mesh="panda_hand_vis" name="panda_hand_visual" rgba="1 1 1 1" />
        <geom pos="0 0 0." quat="0.707107 0 0 0.707107" type="mesh" mesh="panda_hand"  group="0" name="panda_hand_collision"/>
        <!-- This site was added for visualization. -->
        <body name="panda_eef" pos="0 0 0.097" quat="1 0 0 0">
            <site name="grip_site" pos="0 0 0" size="0.01 0.01 0.01" rgba="1 0 0 0.5" type="sphere" group="1"/>
            <site name="panda_ee_x" pos="0.1 0 0" size="0.005 .1"  quat="0.707105  0 0.707108 0 " rgba="1 0 0 0" type="cylinder" group="1"/>
            <site name="panda_ee_y" pos="0 0.1 0" size="0.005 .1" quat="0.707105 0.707108 0 0" rgba="0 1 0 0" type="cylinder" group="1"/>
            <site name="panda_ee_z" pos="0 0 0.1" size="0.005 .1" quat="1 0 0 0" rgba="0 0 1 0" type="cylinder" group="1"/>
            <!-- This site was added for visualization. -->
            <site name="panda_grip_site_cylinder" pos="0 0 0" size="0.005 10" rgba="0 1 0 0.3" type="cylinder" group="1"/>
        </body>
        <body name="panda_leftfinger" pos="0 0 0.0524" quat="0.707107 0 0 0.707107">
            <inertial pos="0 0 0.05" mass="0.1" diaginertia="0.01 0.01 0.005" />
            <joint name="panda_finger_joint1" pos="0 0 0" axis="0 1 0" type="slide" limited="true" range="0.0 0.04" damping="100" armature="1.0" frictionloss="1.0"/>
            <geom type="mesh" contype="0" conaffinity="0" group="1" mesh="panda_finger_vis" name="panda_finger1_visual" rgba="0.499 0.499 0.499 1" />
            <geom type="mesh" group="0" conaffinity="1" contype="0" solref="0.02 1" friction="1 0.005 0.0001" condim="4" mesh="panda_finger" name="panda_finger1_collision"/>
            <body name="panda_finger_joint1_tip" pos="0 0.0085 0.056">
                <inertial pos="0 0 0" quat="0 0 0 1" mass="0.01" diaginertia="0.01 0.01 0.01" />
                <geom size="0.008 0.004 0.008" pos="0 -0.005 -0.015" quat="0 0 0 1" type="box" group="0" solref="0.01 0.5" friction = "2 0.05 0.0001" conaffinity="1" contype="1" name="panda_finger1_pad_collision"/>
            </body>
        </body>
        <body name="panda_rightfinger" pos="0 0 0.0524" quat="0.707107 0 0 0.707107">
            <inertial pos="0 0 0.05" mass="0.1" diaginertia="0.01 0.01 0.005" />
            <joint name="panda_finger_joint2" pos="0 0 0" axis="0 1 0" type="slide" limited="true" range="-0.04 0.0" damping="100" armature="1.0" frictionloss="1.0"/>
            <geom quat="0 0 0 1" type="mesh" contype="0" conaffinity="0" group="1" mesh="panda_finger_vis" name="panda_finger2_visual" rgba="0.499 0.499 0.499 1" />
            <geom quat="0 0 0 1" type="mesh" group="0" conaffinity="1" contype="0" solref="0.02 1" friction="1 0.005 0.0001" condim="4" mesh="panda_finger" name="panda_finger2_collision"/>
            <body name="panda_finger_joint2_tip" pos="0 -0.0085 0.056">
                <inertial pos="0 0 0" quat="0 0 0 1" mass="0.01" diaginertia="0.01 0.01 0.01" />
                <geom size="0.008 0.004 0.008" pos="0 0.005 -0.015" quat="0 0 0 1" type="box" group="0" solref="0.01 0.5" friction = "2 0.05 0.0001" conaffinity="1" contype="1" name="panda_finger2_pad_collision"/>
            </body>
        </body>
    </body>
</mujocoinclude>